Workbook

Sheet Base de datos
B4: BASE DE DATOS DE UNA PAPELERIA
B5: Coodigo de barras | C5: Nombre del producto | D5: Color | E5: Marca | F5: Existencia | G5: No. De Ventas | H5: Precio de Compra | I5: Precio de Venta | J5: MONTO | K5: Ganancia por venta | L5: Ganancia por total vendido
B6: 19081001 | C6: Sacapuntas de plastico | D6: Rojo | E6: Pelikan | F6: 6 | G6: 39 | H6: 10 | I6: 15 | J6: =G6*I6 -> 585 | K6: =I6-H6 -> 5 | L6: =K6*G6 -> 195
B7: 19081002 | C7: Sacapuntas de plastico | D7: Azul | E7: Pelikan | F7: 7 | G7: 47 | H7: 10 | I7: 15 | J7: =I7*G7 -> 705 | K7: =I7-H7 -> 5 | L7: =K7*G7 -> 235
B8: 19081003 | C8: Sacapuntas de plastico | D8: Verde | E8: Pelikan | F8: 25 | G8: 57 | H8: 10 | I8: 15 | J8: =I8*G8 -> 855 | K8: =I8-H8 -> 5 | L8: =K8*G8 -> 285
B9: 19081004 | C9: Sacapuntas de plastico | D9: Morado | E9: Pelikan | F9: 24 | G9: 32 | H9: 10 | I9: 15 | J9: =I9*G9 -> 480 | K9: =I9-H9 -> 5 | L9: =K9*G9 -> 160
B10: 19081005 | C10: Sacapuntas de plastico | D10: Naranja | E10: Maped | F10: 11 | G10: 36 | H10: 13 | I10: 18 | J10: =I10*G10 -> 648 | K10: =I10-H10 -> 5 | L10: =K10*G10 -> 180
B11: 19081006 | C11: Sacapuntas de plastico | D11: Amarillo | E11: Maped | F11: 19 | G11: 19 | H11: 13 | I11: 18 | J11: =I11*G11 -> 342 | K11: =I11-H11 -> 5 | L11: =K11*G11 -> 95
B12: 19081007 | C12: Sacapuntas de plastico | D12: Rojo | E12: Maped | F12: 21 | G12: 70 | H12: 13 | I12: 18 | J12: =I12*G12 -> 1260 | K12: =I12-H12 -> 5 | L12: =K12*G12 -> 350
B13: 19081008 | C13: Sacapuntas de plastico | D13: Azul | E13: Maped | F13: 18 | G13: 28 | H13: 13 | I13: 18 | J13: =I13*G13 -> 504 | K13: =I13-H13 -> 5 | L13: =K13*G13 -> 140
B14: 19081009 | C14: Sacapuntas de plastico | D14: Verde | E14: Maped | F14: 28 | G14: 56 | H14: 13 | I14: 18 | J14: =I14*G14 -> 1008 | K14: =I14-H14 -> 5 | L14: =K14*G14 -> 280
B15: 19081010 | C15: Sacapuntas de plastico | D15: Rojo | E15: Norma | F15: 12 | G15: 54 | H15: 9 | I15: 14 | J15: =I15*G15 -> 756 | K15: =I15-H15 -> 5 | L15: =K15*G15 -> 270
B16: 19081011 | C16: Sacapuntas de plastico | D16: Rosa | E16: Norma | F16: 21 | G16: 69 | H16: 9 | I16: 14 | J16: =I16*G16 -> 966 | K16: =I16-H16 -> 5 | L16: =K16*G16 -> 345
B17: 19081012 | C17: Sacapuntas de plastico | D17: Negro | E17: Norma | F17: 10 | G17: 21 | H17: 9 | I17: 14 | J17: =I17*G17 -> 294 | K17: =I17-H17 -> 5 | L17: =K17*G17 -> 105
B18: 19081013 | C18: Sacapuntas de plastico | D18: Azul | E18: Norma | F18: 6 | G18: 42 | H18: 9 | I18: 14 | J18: =I18*G18 -> 588 | K18: =I18-H18 -> 5 | L18: =K18*G18 -> 210
... B123: 19081118 | C123: Hoja | D123: Blanco | E123: Tony | F123: 19 | G123: 52 | H123: 0.5 | I123: 2 | J123: =I123*G123 -> 104 | K123: =I123-H123 -> 1.5 | L123: =K123*G123 -> 78

Sheet Reporte 1
A2: 1) Monto recaudado por producto ya vendido
A3: FILTROS | D3: FORMULAS | G3: TABLA DINAMICA
A4: Producto | B4: Monto | D4: Producto | E4: Monto | G4: Row Labels | H4: Sum of MONTO
A5: Boligrafo | B5: 4468 | D5: Boligrafo | E5: =SUMIF('Base de datos'!C6:C124,"Boligrafo",'Base de datos'!J6:J123) -> 4468 | G5: Boligrafo | H5: 4468
A6: Borrador de goma | B6: 2693 | D6: Borrador de goma | E6: =SUMIF('Base de datos'!C7:C125,"Borrador de goma",'Base de datos'!J7:J124) -> 2693 | G6: Borrador de goma | H6: 2693
A7: Borrador de migajon | B7: 4519 | D7: Borrador de migajon | E7: =SUMIF('Base de datos'!C8:C126,"Borrador de migajon ",'Base de datos'!J8:J125) -> 4519 | G7: Borrador de migajon | H7: 4519
A8: Caja de colores 24pz | B8: 53622 | D8: Caja de colores 24pz | E8: =SUMIF('Base de datos'!C9:C127,"Caja de colores 24pz",'Base de datos'!J9:J126) -> 53622 | G8: Caja de colores 24pz | H8: 53622
A9: Cartulina | B9: 1840 | D9: Cartulina | E9: =SUMIF('Base de datos'!C10:C128,"Cartulina",'Base de datos'!J10:J127) -> 1840 | G9: Cartulina | H9: 1840
A10: Hoja | B10: 790 | D10: Hoja | E10: =SUMIF('Base de datos'!C11:C129,"Hoja",'Base de datos'!J11:J128) -> 790 | G10: Hoja | H10: 790
A11: Lápiz | B11: 1414 | D11: Lápiz | E11: =SUMIF('Base de datos'!C12:C130,"Lápiz",'Base de datos'!J12:J129) -> 1414 | G11: Lápiz | H11: 1414
A12: Libreta de Cuadros | B12: 38430 | D12: Libreta de Cuadros | E12: =SUMIF('Base de datos'!C13:C131,"Libreta de Cuadros",'Base de datos'!J13:J130) -> 38430 | G12: Libreta de Cuadros | H12: 38430
A13: Libreta de Rayas | B13: 44495 | D13: Libreta de Rayas | E13: =SUMIF('Base de datos'!C14:C132,"Libreta de Rayas",'Base de datos'!J14:J131) -> 44495 | G13: Libreta de Rayas | H13: 44495
A14: Pegamento en barra | B14: 4203 | D14: Pegamento en barra | E14: =SUMIF('Base de datos'!C15:C133,"Pegamento en barra",'Base de datos'!J15:J132) -> 4203 | G14: Pegamento en barra | H14: 4203
A15: Pegamento liquido | B15: 6320 | D15: Pegamento liquido | E15: =SUMIF('Base de datos'!C16:C134,"Pegamento liquido",'Base de datos'!J16:J133) -> 6320 | G15: Pegamento liquido | H15: 6320
A16: Pintura Acrilica | B16: 8115 | D16: Pintura Acrilica | E16: =SUMIF('Base de datos'!C17:C135,"Pintura Acrilica",'Base de datos'!J17:J134) -> 8115 | G16: Pintura Acrilica | H16: 8115
A17: Plumon para pizarron | B17: 11530 | D17: Plumon para pizarron | E17: =SUMIF('Base de datos'!C18:C136,"Plumon para pizarron",'Base de datos'!J18:J135) -> 11530 | G17: Plumon para pizarron | H17: 11530
A18: Sacapuntas de plastico | B18: 8991 | D18: Sacapuntas de plastico | E18: =SUMIF('Base de datos'!C6:C18,"Sacapuntas de plastico",'Base de datos'!J6:J18) -> 8991 | G18: Sacapuntas de plastico | H18: 8991
A19: TOTAL | B19: =SUM(B5:B18) -> 191430 | D19: TOTAL | E19: =SUM(E5:E18) -> 191430 | G19: Grand Total | H19: 191430

Sheet Reporte 2
C4: 2) Ganancia de productos
C7: Filtros
C8: Producto | D8: Total Ventas | E8: Ganancia
C9: Sacapuntas de Plastico | D9: 570 | E9: 2850
C10: Borrador de Goma | D10: 168 | E10: 1133
C11: Borrador de Migajon | D11: 95 | E11: 1724
C12: Pegamento Líquido | D12: 164 | E12: 1115
C13: Pegamento en Barra | D13: 215 | E13: 1658
C14: Lápiz | D14: 224 | E14: 515
C15: Plumon Para Pizarron | D15: 348 | E15: 3480
C16: Caja de Colores | D16: 345 | E16: 5142
C17: Bolígrafo | D17: 430 | E17: 1216
C18: Pintura Acrílica | D18: 541 | E18: 2705
C19: Libreta de Rayas | D19: 669 | E19: 15305
C20: Libreta de Cuadros | D20: 590 | E20: 13295
... C22: Hoja | D22: 395 | E22: 592
D24: Total de Ganancia: | E24: 51834.5
C27: Formulas
C28: Producto | D28: Total Ventas | E28: Ganancia
C29: Sacapuntas de Plastico | D29: =SUM('Base de datos'!G6:G18) -> 570 | E29: =SUM('Base de datos'!L6:L18) -> 2850
C30: Borrador de Goma | D30: =SUM('Base de datos'!G19:G22) -> 168 | E30: =SUM('Base de datos'!L19:L22) -> 1133
C31: Borrador de Migajon | D31: =SUM('Base de datos'!G23:G25) -> 95 | E31: =SUM('Base de datos'!L23:L25) -> 1724
C32: Pegamento Líquido | D32: =SUM('Base de datos'!G26:G29) -> 164 | E32: =SUM('Base de datos'!L26:L29) -> 1115
C33: Pegamento en Barra | D33: =SUM('Base de datos'!G30:G33) -> 215 | E33: =SUM('Base de datos'!L30:L33) -> 1658
C34: Lápiz | D34: =SUM('Base de datos'!G34:G38) -> 224 | E34: =SUM('Base de datos'!L34:L38) -> 515
C35: Plumon Para Pizarron | D35: =SUM('Base de datos'!G39:G46) -> 348 | E35: =SUM('Base de datos'!L39:L46) -> 3480
C36: Caja de Colores | D36: =SUM('Base de datos'!G47:G53) -> 345 | E36: =SUM('Base de datos'!L47:L53) -> 5142
C37: Bolígrafo | D37: =SUM('Base de datos'!G54:G65) -> 430 | E37: =SUM('Base de datos'!L54:L65) -> 1216
C38: Pintura Acrílica | D38: =SUM('Base de datos'!G66:G76) -> 541 | E38: =SUM('Base de datos'!L66:L76) -> 2705
C39: Libreta de Rayas | D39: =SUM('Base de datos'!G77:G91) -> 669 | E39: =SUM('Base de datos'!L77:L91) -> 15305
C40: Libreta de Cuadros | D40: =SUM('Base de datos'!G92:G106) -> 590 | E40: =SUM('Base de datos'!L92:L106) -> 13295
C41: Cartulina | D41: =SUM('Base de datos'!G107:G114) -> 368 | E41: =SUM('Base de datos'!L107:L114) -> 1104
C42: Hoja | D42: =SUM('Base de datos'!G115:G123) -> 395 | E42: =SUM('Base de datos'!L115:L123) -> 592.5
D44: TOTAL DE GANANCIA | E44: =SUM(E29:E42) -> 51834.5
C47: Tabla Dinámica
C49: Etiquetas de fila | D49: Suma de Total Ventas | E49: Suma de Ganancia
C50: Bolígrafo | D50: 430 | E50: 1216
C51: Borrador de Goma | D51: 168 | E51: 1133
C52: Borrador de Migajon | D52: 95 | E52: 1724
C53: Caja de Colores | D53: 345 | E53: 5142
...

Sheet Reporte 3
B2: 3)Numero de proudctos en existencia por marca
B4: FILTROS | G4: FORMULAS | L4: TABLA DINAMICA
B5: Marca | C5: # de productos | G5: Marca | H5: # de productos | L5: Etiquetas de fila | M5: Suma de Existencia
B6: Azor | C6: 24 | G6: Azor | H6: =SUMIF('Base de datos'!E6:E123,"Azor",'Base de datos'!F6:F123) -> 24 | L6: Azor | M6: 24
B7: Barrilito | C7: 12 | G7: Barrilito | H7: =SUMIF('Base de datos'!E6:E123,"Barrilito",'Base de datos'!F6:F123) -> 12 | L7: Barrilito | M7: 12
B8: Bic | C8: 114 | G8: Bic | H8: =SUMIF('Base de datos'!E7:E124,"Bic",'Base de datos'!F7:F124) -> 114 | L8: Bic | M8: 114
B9: Bully | C9: 40 | G9: Bully | H9: =SUMIF('Base de datos'!E8:E125,"Bully",'Base de datos'!F8:F125) -> 40 | L9: Bully | M9: 40
B10: Crayola | C10: 17 | G10: Crayola | H10: =SUMIF('Base de datos'!E9:E126,"Crayola",'Base de datos'!F9:F126) -> 17 | L10: Crayola | M10: 17
B11: Dixon | C11: 54 | G11: Dixon | H11: =SUMIF('Base de datos'!E10:E127,"Dixon",'Base de datos'!F10:F127) -> 54 | L11: Dixon | M11: 54
B12: Elmer's | C12: 29 | G12: Elmer's | H12: =SUMIF('Base de datos'!E11:E128,"Elmer's",'Base de datos'!F11:F128) -> 29 | L12: Elmer's | M12: 29
B13: Expo | C13: 65 | G13: Expo | H13: =SUMIF('Base de datos'!E12:E129,"Expo",'Base de datos'!F12:F129) -> 65 | L13: Expo | M13: 65
B14: Faber Castell | C14: 25 | G14: Faber Castell | H14: =SUMIF('Base de datos'!E13:E130,"FaberCastell",'Base de datos'!F13:F130) -> 25 | L14: FaberCastell | M14: 25
B15: Magistral | C15: 103 | G15: Magistral | H15: =SUMIF('Base de datos'!E14:E131,"Magistral",'Base de datos'!F14:F131) -> 103 | L15: Magistral | M15: 103
B16: Maped | C16: 128 | G16: Maped | H16: =SUMIF('Base de datos'!E6:E123,"Maped",'Base de datos'!F6:F123) -> 128 | L16: Maped | M16: 128
B17: Norma | C17: 304 | G17: Norma | H17: =SUMIF('Base de datos'!E6:E123,"Norma",'Base de datos'!F6:F123) -> 304 | L17: Norma | M17: 304
B18: Papper Mate | C18: 65 | G18: Papper Mate | H18: =SUMIF('Base de datos'!E17:E134,"Papper Mate",'Base de datos'!F17:F134) -> 65 | L18: Papper Mate | M18: 65
B19: Pelikan | C19: 104 | G19: Pelikan | H19: 104 | L19: Pelikan | M19: 104
B20: Pilot | C20: 50 | G20: Pilot | H20: =SUMIF('Base de datos'!E19:E136,"Pilot",'Base de datos'!F19:F136) -> 50 | L20: Pilot | M20: 50
B21: Politec | C21: 168 | G21: Politec | H21: =SUMIF('Base de datos'!E20:E137,"Politec",'Base de datos'!F20:F137) -> 168 | L21: Politec | M21: 168
B22: Prismacolor | C22: 56 | G22: Prismacolor | H22: =SUMIF('Base de datos'!E21:E138,"Prismacolor",'Base de datos'!F21:F138) -> 56 | L22: Prismacolor | M22: 56
B23: Resistol | C23: 36 | G23: Resistol | H23: =SUMIF('Base de datos'!E22:E139,"Resistol",'Base de datos'!F22:F139) -> 36 | L23: Resistol | M23: 36
B24: Scribe | C24: 214 | G24: Scribe | H24: 214 | L24: Scribe | M24: 214
B25: Tony | C25: 332 | G25: Tony | H25: =SUMIF('Base de datos'!E6:E123,"Tony",'Base de datos'!F6:F123) -> 332 | L25: Tony | M25: 332
B26: TOTAL | C26: =SUM(C6:C25) -> 1940 | G26: TOTAL | H26: =SUM(H6:H25) -> 1940 | L26: Total general | M26: 1940

Sheet Reporte 4
B2: 4) % de ventas en cajas de colores por sus marcas

Sheet Reporte 5
B2: 5 ) Porcentaje en libertas vendidas de rayas y cuadros
B5: FILTROS
B6: Tipo de libera | C6: Cantidad de libretas vendidas | D6: Porcentaje
B7: Libreta de Rayas | C7: 669 | D7: =C7 * 1/C9 -> 0.53137411
B8: Libreta de Cuadros | C8: 590 | D8: =C8 * 1/C9 -> 0.46862589
B9: TOTAL | C9: =SUM(C7:C8) -> 1259 | D9: =SUM(D7:D8) -> 1
B12: FORMULAS
B13: Tipo de libera | C13: Cantidad de libretas vendidas | D13: Porcentaje
B14: Libreta de Rayas | C14: =SUMIF('Base de datos'!C6:C123,"Libreta de Rayas",'Base de datos'!G6:G123) -> 669 | D14: =C14/C16 -> 0.53137411
B15: Libreta de Cuadros | C15: =SUMIF('Base de datos'!C6:C123,"Libreta de Cuadros",'Base de datos'!G6:G123) -> 590 | D15: =C15/C16 -> 0.46862589
B16: TOTAL | C16: =SUM(C14:C15) -> 1259 | D16: =SUM(D14:D15) -> 1
B20: TABLA DINÁMICA
B21: Etiquetas de fila | C21: Suma de No. De Ventas
B22: Libreta de Cuadros | C22: 0.46862589
B23: Libreta de Rayas | C23: 0.53137411
B24: Total general | C24: 1
